Workbook

Sheet CBSMprovisões
A1: Data de lançamento | B1: Nº transação | C1: Origem | D1: Nº origem | E1: Ref.3 | F1: Conta de contrapartida | G1: Detalhes | H1: C/D (ML) | I1: Saldo acumulado (MC) | J1: Fornecedor | K1: SubGrupo | L1: Mês/Ano | M1: Empresa | N1: Descrição Conta
C2: SI | I2: 0
A3: 46022 | B3: 8635611 | C3: LC | D3: 8635611 | E3: F009096 | F3: 3313030 | G3: PROV. KRAKOWIAK ADVOGADOS - dez/25 | H3: -242060 | I3: -242060 | J3: =IF($A3="","",IFERROR(_xlfn.XLOOKUP($E3,cbsmfornecedor!$A:$A,cbsmfornecedor!$B:$B),"")) -> KRAKOWIAK ADVOGADOS | K3: =IF($A3="","",IFERROR(_xlfn.XLOOKUP($F3,cbsmpacote!$A:$A,cbsmpacote!$D:$D),"")) -> Services | L3: =IF($A3="","",DATE(YEAR($A3),MONTH($A3),1)) -> 45992 | M3: =IF($A3="","","CBSM") -> CBSM | N3: =IF($A3="","",IFERROR(_xlfn.XLOOKUP($F3,cbsmpacote!$A:$A,cbsmpacote!$B:$B),"")) -> Assessoria Jurídica
A4: 46022 | B4: 8635623 | C4: LC | D4: 8635623 | E4: F009582 | F4: 3313350 | G4: PROV. MENA INTELIGENCIA EM TALENTOS LTDA - dez/25 | H4: -10000 | I4: -252060 | J4: =IF($A4="","",IFERROR(_xlfn.XLOOKUP($E4,cbsmfornecedor!$A:$A,cbsmfornecedor!$B:$B),"")) -> MENA INTELIGENCIA EM TALENTOS LTDA | K4: =IF($A4="","",IFERROR(_xlfn.XLOOKUP($F4,cbsmpacote!$A:$A,cbsmpacote!$D:$D),"")) -> Services | L4: =IF($A4="","",DATE(YEAR($A4),MONTH($A4),1)) -> 45992 | M4: =IF($A4="","","CBSM") -> CBSM | N4: =IF($A4="","",IFERROR(_xlfn.XLOOKUP($F4,cbsmpacote!$A:$A,cbsmpacote!$B:$B),"")) -> Serviços de Consultoria
A5: 46052 | B5: 8652891 | C5: LC | D5: 8652891 | E5: F008870 | F5: 3313160 | G5: PROV. - PARLA CONTAC CENTER S/A - F008870 JAN26 | H5: -24000 | I5: -276060 | J5: =IF($A5="","",IFERROR(_xlfn.XLOOKUP($E5,cbsmfornecedor!$A:$A,cbsmfornecedor!$B:$B),"")) -> PARLA CONTAC CENTER S/A | K5: =IF($A5="","",IFERROR(_xlfn.XLOOKUP($F5,cbsmpacote!$A:$A,cbsmpacote!$D:$D),"")) -> CRM & Call Center | L5: =IF($A5="","",DATE(YEAR($A5),MONTH($A5),1)) -> 46023 | M5: =IF($A5="","","CBSM") -> CBSM | N5: =IF($A5="","",IFERROR(_xlfn.XLOOKUP($F5,cbsmpacote!$A:$A,cbsmpacote!$B:$B),"")) -> Despesas Call Center
A6: 46054 | B6: 8655981 | C6: LC | D6: 8655981 | E6: F009582 | F6: 3313350 | G6: PROV. MENA INTELIGENCIA EM TALENTOS LTDA - dez/25 (Estorno 8635623) | H6: 3551.56 | I6: -272508.44 | J6: =IF($A6="","",IFERROR(_xlfn.XLOOKUP($E6,cbsmfornecedor!$A:$A,cbsmfornecedor!$B:$B),"")) -> MENA INTELIGENCIA EM TALENTOS LTDA | K6: =IF($A6="","",IFERROR(_xlfn.XLOOKUP($F6,cbsmpacote!$A:$A,cbsmpacote!$D:$D),"")) -> Services | L6: =IF($A6="","",DATE(YEAR($A6),MONTH($A6),1)) -> 46054 | M6: =IF($A6="","","CBSM") -> CBSM | N6: =IF($A6="","",IFERROR(_xlfn.XLOOKUP($F6,cbsmpacote!$A:$A,cbsmpacote!$B:$B),"")) -> Serviços de Consultoria
A7: 46080 | B7: 8669549 | C7: LC | D7: 8669549 | E7: F008870 | F7: 3313160 | G7: PROV. PARLA CONTAC CENTER S/A - F008870 - FEV26 | H7: -24000 | I7: -296508.44 | J7: =IF($A7="","",IFERROR(_xlfn.XLOOKUP($E7,cbsmfornecedor!$A:$A,cbsmfornecedor!$B:$B),"")) -> PARLA CONTAC CENTER S/A | K7: =IF($A7="","",IFERROR(_xlfn.XLOOKUP($F7,cbsmpacote!$A:$A,cbsmpacote!$D:$D),"")) -> CRM & Call Center | L7: =IF($A7="","",DATE(YEAR($A7),MONTH($A7),1)) -> 46054 | M7: =IF($A7="","","CBSM") -> CBSM | N7: =IF($A7="","",IFERROR(_xlfn.XLOOKUP($F7,cbsmpacote!$A:$A,cbsmpacote!$B:$B),"")) -> Despesas Call Center
A8: 46112 | B8: 8686394 | C8: LC | D8: 8686394 | E8: F008408 | F8: 3313160 | G8: PROVISÃO 55TELECOM COMUNICAÇÃO LTDA - MARÇO 2026 | H8: -33100 | I8: -329608.44 | J8: =IF($A8="","",IFERROR(_xlfn.XLOOKUP($E8,cbsmfornecedor!$A:$A,cbsmfornecedor!$B:$B),"")) -> 55TELECOM COMUNICAÇÃO LTDA | K8: =IF($A8="","",IFERROR(_xlfn.XLOOKUP($F8,cbsmpacote!$A:$A,cbsmpacote!$D:$D),"")) -> CRM & Call Center | L8: =IF($A8="","",DATE(YEAR($A8),MONTH($A8),1)) -> 46082 | M8: =IF($A8="","","CBSM") -> CBSM | N8: =IF($A8="","",IFERROR(_xlfn.XLOOKUP($F8,cbsmpacote!$A:$A,cbsmpacote!$B:$B),"")) -> Despesas Call Center
A9: 46142 | B9: 8702918 | C9: LC | D9: 8702918 | E9: F005535 | F9: 3211020 | G9: PROV INFOBIP BRASIL SERVICOS DE VALOR ADICIONADO LTDA | H9: -78757.99 | I9: -408366.43 | J9: =IF($A9="","",IFERROR(_xlfn.XLOOKUP($E9,cbsmfornecedor!$A:$A,cbsmfornecedor!$B:$B),"")) -> INFOBIP BRAZIL SERVICOS DE VALOR ADICIONADO LTDA. | K9: =IF($A9="","",IFERROR(_xlfn.XLOOKUP($F9,cbsmpacote!$A:$A,cbsmpacote!$D:$D),"")) -> Other costs - CBSM CAT | L9: =IF($A9="","",DATE(YEAR($A9),MONTH($A9),1)) -> 46113 | M9: =IF($A9="","","CBSM") -> CBSM | N9: =IF($A9="","",IFERROR(_xlfn.XLOOKUP($F9,cbsmpacote!$A:$A,cbsmpacote!$B:$B),"")) -> CAT - Gastos com tecnologia
A10: 46142 | B10: 8702919 | C10: LC | D10: 8702919 | E10: F005535 | F10: 3211020 | G10: PROV INFOBIP BRASIL SERVICOS DE VALOR ADICIONADO LTDA | H10: -45331.47 | I10: -453697.9 | J10: =IF($A10="","",IFERROR(_xlfn.XLOOKUP($E10,cbsmfornecedor!$A:$A,cbsmfornecedor!$B:$B),"")) -> INFOBIP BRAZIL SERVICOS DE VALOR ADICIONADO LTDA. | K10: =IF($A10="","",IFERROR(_xlfn.XLOOKUP($F10,cbsmpacote!$A:$A,cbsmpacote!$D:$D),"")) -> Other costs - CBSM CAT | L10: =IF($A10="","",DATE(YEAR($A10),MONTH($A10),1)) -> 46113 | M10: =IF($A10="","","CBSM") -> CBSM | N10: =IF($A10="","",IFERROR(_xlfn.XLOOKUP($F10,cbsmpacote!$A:$A,cbsmpacote!$B:$B),"")) -> CAT - Gastos com tecnologia
A11: 46171 | B11: 8718557 | C11: LC | D11: 8718557 | E11: F006557 | F11: 3313030 | G11: Provisão MMF e A&F Créditos Previdenciários | H11: -59573.47 | I11: -513271.37 | J11: =IF($A11="","",IFERROR(_xlfn.XLOOKUP($E11,cbsmfornecedor!$A:$A,cbsmfornecedor!$B:$B),"")) -> MOSS, MUZZI, FALCAO, MASSOTE E WERNECK ADVOGADOS ASSOCIADOS | K11: =IF($A11="","",IFERROR(_xlfn.XLOOKUP($F11,cbsmpacote!$A:$A,cbsmpacote!$D:$D),"")) -> Services | L11: =IF($A11="","",DATE(YEAR($A11),MONTH($A11),1)) -> 46143 | M11: =IF($A11="","","CBSM") -> CBSM | N11: =IF($A11="","",IFERROR(_xlfn.XLOOKUP($F11,cbsmpacote!$A:$A,cbsmpacote!$B:$B),"")) -> Assessoria Jurídica
A12: 46171 | B12: 8719033 | C12: LC | D12: 8719033 | E12: F009633 | F12: 3313160 | G12: PROV. CSU S.A - F009633 | H12: -58405.53 | I12: -571676.9 | J12: =IF($A12="","",IFERROR(_xlfn.XLOOKUP($E12,cbsmfornecedor!$A:$A,cbsmfornecedor!$B:$B),"")) -> CSU DIGITAL | K12: =IF($A12="","",IFERROR(_xlfn.XLOOKUP($F12,cbsmpacote!$A:$A,cbsmpacote!$D:$D),"")) -> CRM & Call Center | L12: =IF($A12="","",DATE(YEAR($A12),MONTH($A12),1)) -> 46143 | M12: =IF($A12="","","CBSM") -> CBSM | N12: =IF($A12="","",IFERROR(_xlfn.XLOOKUP($F12,cbsmpacote!$A:$A,cbsmpacote!$B:$B),"")) -> Despesas Call Center
A13: 46171 | B13: 8719034 | C13: LC | D13: 8719034 | E13: F008408 | F13: 3313160 | G13: PROV. 55TELECOM COMUNICAÇÃO LTDA - F008408 | H13: -8847.57 | I13: -580524.47 | J13: =IF($A13="","",IFERROR(_xlfn.XLOOKUP($E13,cbsmfornecedor!$A:$A,cbsmfornecedor!$B:$B),"")) -> 55TELECOM COMUNICAÇÃO LTDA | K13: =IF($A13="","",IFERROR(_xlfn.XLOOKUP($F13,cbsmpacote!$A:$A,cbsmpacote!$D:$D),"")) -> CRM & Call Center | L13: =IF($A13="","",DATE(YEAR($A13),MONTH($A13),1)) -> 46143 | M13: =IF($A13="","","CBSM") -> CBSM | N13: =IF($A13="","",IFERROR(_xlfn.XLOOKUP($F13,cbsmpacote!$A:$A,cbsmpacote!$B:$B),"")) -> Despesas Call Center
A14: 46171 | B14: 8719035 | C14: LC | D14: 8719035 | E14: F008547 | F14: 3313161 | G14: PROV. QUEST TECNOLOGIA LTDA - F008547 | H14: -10500 | I14: -591024.47 | J14: =IF($A14="","",IFERROR(_xlfn.XLOOKUP($E14,cbsmfornecedor!$A:$A,cbsmfornecedor!$B:$B),"")) -> QUEST TECNOLOGIA LTDA | K14: =IF($A14="","",IFERROR(_xlfn.XLOOKUP($F14,cbsmpacote!$A:$A,cbsmpacote!$D:$D),"")) -> CRM & Call Center | L14: =IF($A14="","",DATE(YEAR($A14),MONTH($A14),1)) -> 46143 | M14: =IF($A14="","","CBSM") -> CBSM | N14: =IF($A14="","",IFERROR(_xlfn.XLOOKUP($F14,cbsmpacote!$A:$A,cbsmpacote!$B:$B),"")) -> Pesquisa
... A30: 46171 | B30: 8719257 | C30: LC | D30: 8719257 | E30: F009635 | F30: 3313380 | G30: PROV. ENYGMA TECNOLOGIA EM INFORMATICA LTDA | H30: -15400 | I30: -1358729.6 | J30: =IF($A30="","",IFERROR(_xlfn.XLOOKUP($E30,cbsmfornecedor!$A:$A,cbsmfornecedor!$B:$B),"")) -> ENYGMA TECNOLOGIA EM INFORMATICA LTDA | K30: =IF($A30="","",IFERROR(_xlfn.XLOOKUP($F30,cbsmpacote!$A:$A,cbsmpacote!$D:$D),"")) -> IT & Telecom | L30: =IF($A30="","",DATE(YEAR($A30),MONTH($A30),1)) -> 46143 | M30: =IF($A30="","","CBSM") -> CBSM | N30: =IF($A30="","",IFERROR(_xlfn.XLOOKUP($F30,cbsmpacote!$A:$A,cbsmpacote!$B:$B),"")) -> Suporte Técnico
J32: =IF($A32="","",IFERROR(_xlfn.XLOOKUP($E32,cbsmfornecedor!$A:$A,cbsmfornecedor!$B:$B),"")) | K32: =IF($A32="","",IFERROR(_xlfn.XLOOKUP($F32,cbsmpacote!$A:$A,cbsmpacote!$D:$D),"")) | L32: =IF($A32="","",DATE(YEAR($A32),MONTH($A32),1)) | M32: =IF($A32="","","CBSM") | N32: =IF($A32="","",IFERROR(_xlfn.XLOOKUP($F32,cbsmpacote!$A:$A,cbsmpacote!$B:$B),""))
J33: =IF($A33="","",IFERROR(_xlfn.XLOOKUP($E33,cbsmfornecedor!$A:$A,cbsmfornecedor!$B:$B),"")) | K33: =IF($A33="","",IFERROR(_xlfn.XLOOKUP($F33,cbsmpacote!$A:$A,cbsmpacote!$D:$D),"")) | L33: =IF($A33="","",DATE(YEAR($A33),MONTH($A33),1)) | M33: =IF($A33="","","CBSM") | N33: =IF($A33="","",IFERROR(_xlfn.XLOOKUP($F33,cbsmpacote!$A:$A,cbsmpacote!$B:$B),""))
J34: =IF($A34="","",IFERROR(_xlfn.XLOOKUP($E34,cbsmfornecedor!$A:$A,cbsmfornecedor!$B:$B),"")) | K34: =IF($A34="","",IFERROR(_xlfn.XLOOKUP($F34,cbsmpacote!$A:$A,cbsmpacote!$D:$D),"")) | L34: =IF($A34="","",DATE(YEAR($A34),MONTH($A34),1)) | M34: =IF($A34="","","CBSM") | N34: =IF($A34="","",IFERROR(_xlfn.XLOOKUP($F34,cbsmpacote!$A:$A,cbsmpacote!$B:$B),""))
J35: =IF($A35="","",IFERROR(_xlfn.XLOOKUP($E35,cbsmfornecedor!$A:$A,cbsmfornecedor!$B:$B),"")) | K35: =IF($A35="","",IFERROR(_xlfn.XLOOKUP($F35,cbsmpacote!$A:$A,cbsmpacote!$D:$D),"")) | L35: =IF($A35="","",DATE(YEAR($A35),MONTH($A35),1)) | M35: =IF($A35="","","CBSM") | N35: =IF($A35="","",IFERROR(_xlfn.XLOOKUP($F35,cbsmpacote!$A:$A,cbsmpacote!$B:$B),""))
J36: =IF($A36="","",IFERROR(_xlfn.XLOOKUP($E36,cbsmfornecedor!$A:$A,cbsmfornecedor!$B:$B),"")) | K36: =IF($A36="","",IFERROR(_xlfn.XLOOKUP($F36,cbsmpacote!$A:$A,cbsmpacote!$D:$D),"")) | L36: =IF($A36="","",DATE(YEAR($A36),MONTH($A36),1)) | M36: =IF($A36="","","CBSM") | N36: =IF($A36="","",IFERROR(_xlfn.XLOOKUP($F36,cbsmpacote!$A:$A,cbsmpacote!$B:$B),""))
J37: =IF($A37="","",IFERROR(_xlfn.XLOOKUP($E37,cbsmfornecedor!$A:$A,cbsmfornecedor!$B:$B),"")) | K37: =IF($A37="","",IFERROR(_xlfn.XLOOKUP($F37,cbsmpacote!$A:$A,cbsmpacote!$D:$D),"")) | L37: =IF($A37="","",DATE(YEAR($A37),MONTH($A37),1)) | M37: =IF($A37="","","CBSM") | N37: =IF($A37="","",IFERROR(_xlfn.XLOOKUP($F37,cbsmpacote!$A:$A,cbsmpacote!$B:$B),""))
J38: =IF($A38="","",IFERROR(_xlfn.XLOOKUP($E38,cbsmfornecedor!$A:$A,cbsmfornecedor!$B:$B),"")) | K38: =IF($A38="","",IFERROR(_xlfn.XLOOKUP($F38,cbsmpacote!$A:$A,cbsmpacote!$D:$D),"")) | L38: =IF($A38="","",DATE(YEAR($A38),MONTH($A38),1)) | M38: =IF($A38="","","CBSM") | N38: =IF($A38="","",IFERROR(_xlfn.XLOOKUP($F38,cbsmpacote!$A:$A,cbsmpacote!$B:$B),""))
J39: =IF($A39="","",IFERROR(_xlfn.XLOOKUP($E39,cbsmfornecedor!$A:$A,cbsmfornecedor!$B:$B),"")) | K39: =IF($A39="","",IFERROR(_xlfn.XLOOKUP($F39,cbsmpacote!$A:$A,cbsmpacote!$D:$D),"")) | L39: =IF($A39="","",DATE(YEAR($A39),MONTH($A39),1)) | M39: =IF($A39="","","CBSM") | N39: =IF($A39="","",IFERROR(_xlfn.XLOOKUP($F39,cbsmpacote!$A:$A,cbsmpacote!$B:$B),""))
J40: =IF($A40="","",IFERROR(_xlfn.XLOOKUP($E40,cbsmfornecedor!$A:$A,cbsmfornecedor!$B:$B),"")) | K40: =IF($A40="","",IFERROR(_xlfn.XLOOKUP($F40,cbsmpacote!$A:$A,cbsmpacote!$D:$D),"")) | L40: =IF($A40="","",DATE(YEAR($A40),MONTH($A40),1)) | M40: =IF($A40="","","CBSM") | N40: =IF($A40="","",IFERROR(_xlfn.XLOOKUP($F40,cbsmpacote!$A:$A,cbsmpacote!$B:$B),""))
J41: =IF($A41="","",IFERROR(_xlfn.XLOOKUP($E41,cbsmfornecedor!$A:$A,cbsmfornecedor!$B:$B),"")) | K41: =IF($A41="","",IFERROR(_xlfn.XLOOKUP($F41,cbsmpacote!$A:$A,cbsmpacote!$D:$D),"")) | L41: =IF($A41="","",DATE(YEAR($A41),MONTH($A41),1)) | M41: =IF($A41="","","CBSM") | N41: =IF($A41="","",IFERROR(_xlfn.XLOOKUP($F41,cbsmpacote!$A:$A,cbsmpacote!$B:$B),""))
J42: =IF($A42="","",IFERROR(_xlfn.XLOOKUP($E42,cbsmfornecedor!$A:$A,cbsmfornecedor!$B:$B),"")) | K42: =IF($A42="","",IFERROR(_xlfn.XLOOKUP($F42,cbsmpacote!$A:$A,cbsmpacote!$D:$D),"")) | L42: =IF($A42="","",DATE(YEAR($A42),MONTH($A42),1)) | M42: =IF($A42="","","CBSM") | N42: =IF($A42="","",IFERROR(_xlfn.XLOOKUP($F42,cbsmpacote!$A:$A,cbsmpacote!$B:$B),""))
J43: =IF($A43="","",IFERROR(_xlfn.XLOOKUP($E43,cbsmfornecedor!$A:$A,cbsmfornecedor!$B:$B),"")) | K43: =IF($A43="","",IFERROR(_xlfn.XLOOKUP($F43,cbsmpacote!$A:$A,cbsmpacote!$D:$D),"")) | L43: =IF($A43="","",DATE(YEAR($A43),MONTH($A43),1)) | M43: =IF($A43="","","CBSM") | N43: =IF($A43="","",IFERROR(_xlfn.XLOOKUP($F43,cbsmpacote!$A:$A,cbsmpacote!$B:$B),""))
... J200: =IF($A200="","",IFERROR(_xlfn.XLOOKUP($E200,cbsmfornecedor!$A:$A,cbsmfornecedor!$B:$B),"")) | K200: =IF($A200="","",IFERROR(_xlfn.XLOOKUP($F200,cbsmpacote!$A:$A,cbsmpacote!$D:$D),"")) | L200: =IF($A200="","",DATE(YEAR($A200),MONTH($A200),1)) | M200: =IF($A200="","","CBSM") | N200: =IF($A200="","",IFERROR(_xlfn.XLOOKUP($F200,cbsmpacote!$A:$A,cbsmpacote!$B:$B),""))

Sheet Noverdeprovisões
A1: Data de lançamento | B1: Nº transação | C1: Origem | D1: Nº origem | E1: Ref.3 | F1: Conta de contrapartida | G1: Detalhes | H1: C/D (ML) | I1: Saldo acumulado (MC) | J1: Fornecedor | K1: SubGrupo | L1: Mês/Ano | M1: Empresa | N1: Descrição Conta
C2: SI | I2: 0
A3: 45989 | B3: 17345 | C3: LC | D3: 17345 | E3: F000034 | F3: 81763005005 | G3: PROV. BOA VISTA SERVICOS S.A. - nov/25 | H3: -30000 | I3: -30000 | J3: =IF($A3="","",IFERROR(_xlfn.XLOOKUP($E3,noverdefornecedor!$A:$A,noverdefornecedor!$B:$B),"")) -> BOA VISTA SERVICOS S.A. | K3: =IF($A3="","",IFERROR(_xlfn.XLOOKUP($F3,noverdepacote!$A:$A,noverdepacote!$D:$D),"")) -> Other costs - NoVerde | L3: =IF($A3="","",DATE(YEAR($A3),MONTH($A3),1)) -> 45962 | M3: =IF($A3="","","Noverde") -> Noverde | N3: =IF($A3="","",IFERROR(_xlfn.XLOOKUP($F3,noverdepacote!$A:$A,noverdepacote!$B:$B),"")) -> Custo de Cobrança (Custo)
A4: 46022 | B4: 17852 | C4: LC | D4: 17852 | E4: F000034 | F4: 81763005005 | G4: PROV. BOA VISTA SERVICOS S.A. - dez/25 | H4: -30000 | I4: -60000 | J4: =IF($A4="","",IFERROR(_xlfn.XLOOKUP($E4,noverdefornecedor!$A:$A,noverdefornecedor!$B:$B),"")) -> BOA VISTA SERVICOS S.A. | K4: =IF($A4="","",IFERROR(_xlfn.XLOOKUP($F4,noverdepacote!$A:$A,noverdepacote!$D:$D),"")) -> Other costs - NoVerde | L4: =IF($A4="","",DATE(YEAR($A4),MONTH($A4),1)) -> 45992 | M4: =IF($A4="","","Noverde") -> Noverde | N4: =IF($A4="","",IFERROR(_xlfn.XLOOKUP($F4,noverdepacote!$A:$A,noverdepacote!$B:$B),"")) -> Custo de Cobrança (Custo)
A5: 46052 | B5: 18451 | C5: LC | D5: 18451 | E5: F000072 | F5: 81745009011 | G5: PROV. SERASA S.A - jan/26 | H5: -271400 | I5: -331400 | J5: =IF($A5="","",IFERROR(_xlfn.XLOOKUP($E5,noverdefornecedor!$A:$A,noverdefornecedor!$B:$B),"")) -> SERASA S.A | K5: =IF($A5="","",IFERROR(_xlfn.XLOOKUP($F5,noverdepacote!$A:$A,noverdepacote!$D:$D),"")) -> Other costs - NoVerde | L5: =IF($A5="","",DATE(YEAR($A5),MONTH($A5),1)) -> 46023 | M5: =IF($A5="","","Noverde") -> Noverde | N5: =IF($A5="","",IFERROR(_xlfn.XLOOKUP($F5,noverdepacote!$A:$A,noverdepacote!$B:$B),"")) -> Custo de Marketing (Custo)
A6: 46052 | B6: 18465 | C6: LC | D6: 18465 | E6: F000034 | F6: 81763005005 | G6: PROV. BOA VISTA SERVICOS S.A. - jan/26 | H6: -30000 | I6: -361400 | J6: =IF($A6="","",IFERROR(_xlfn.XLOOKUP($E6,noverdefornecedor!$A:$A,noverdefornecedor!$B:$B),"")) -> BOA VISTA SERVICOS S.A. | K6: =IF($A6="","",IFERROR(_xlfn.XLOOKUP($F6,noverdepacote!$A:$A,noverdepacote!$D:$D),"")) -> Other costs - NoVerde | L6: =IF($A6="","",DATE(YEAR($A6),MONTH($A6),1)) -> 46023 | M6: =IF($A6="","","Noverde") -> Noverde | N6: =IF($A6="","",IFERROR(_xlfn.XLOOKUP($F6,noverdepacote!$A:$A,noverdepacote!$B:$B),"")) -> Custo de Cobrança (Custo)
A7: 46080 | B7: 18971 | C7: LC | D7: 18971 | E7: F000034 | F7: 81763005006 | G7: PROV. BOA VISTA SERVICOS S.A. - fev/26 | H7: -250000 | I7: -611400 | J7: =IF($A7="","",IFERROR(_xlfn.XLOOKUP($E7,noverdefornecedor!$A:$A,noverdefornecedor!$B:$B),"")) -> BOA VISTA SERVICOS S.A. | K7: =IF($A7="","",IFERROR(_xlfn.XLOOKUP($F7,noverdepacote!$A:$A,noverdepacote!$D:$D),"")) -> Other costs - NoVerde | L7: =IF($A7="","",DATE(YEAR($A7),MONTH($A7),1)) -> 46054 | M7: =IF($A7="","","Noverde") -> Noverde | N7: =IF($A7="","",IFERROR(_xlfn.XLOOKUP($F7,noverdepacote!$A:$A,noverdepacote!$B:$B),"")) -> Custos de Credito
A8: 46080 | B8: 18997 | C8: LC | D8: 18997 | E8: F000034 | F8: 81763005005 | G8: PROV. BOA VISTA SERVICOS S.A. - F000034 - FEV26 | H8: -30000 | I8: -641400 | J8: =IF($A8="","",IFERROR(_xlfn.XLOOKUP($E8,noverdefornecedor!$A:$A,noverdefornecedor!$B:$B),"")) -> BOA VISTA SERVICOS S.A. | K8: =IF($A8="","",IFERROR(_xlfn.XLOOKUP($F8,noverdepacote!$A:$A,noverdepacote!$D:$D),"")) -> Other costs - NoVerde | L8: =IF($A8="","",DATE(YEAR($A8),MONTH($A8),1)) -> 46054 | M8: =IF($A8="","","Noverde") -> Noverde | N8: =IF($A8="","",IFERROR(_xlfn.XLOOKUP($F8,noverdepacote!$A:$A,noverdepacote!$B:$B),"")) -> Custo de Cobrança (Custo)
A9: 46080 | B9: 18998 | C9: LC | D9: 18998 | E9: F000132 | F9: 81763005005 | G9: PROV. Gestora de Inteligência de Crédito S.A. - F000132 - FEV26 | H9: -30000 | I9: -671400 | J9: =IF($A9="","",IFERROR(_xlfn.XLOOKUP($E9,noverdefornecedor!$A:$A,noverdefornecedor!$B:$B),"")) -> Gestora de Inteligência de Crédito S.A. | K9: =IF($A9="","",IFERROR(_xlfn.XLOOKUP($F9,noverdepacote!$A:$A,noverdepacote!$D:$D),"")) -> Other costs - NoVerde | L9: =IF($A9="","",DATE(YEAR($A9),MONTH($A9),1)) -> 46054 | M9: =IF($A9="","","Noverde") -> Noverde | N9: =IF($A9="","",IFERROR(_xlfn.XLOOKUP($F9,noverdepacote!$A:$A,noverdepacote!$B:$B),"")) -> Custo de Cobrança (Custo)
A10: 46112 | B10: 19656 | C10: LC | D10: 19656 | E10: F000102 | F10: 81757104017 | G10: PROVISÃO PARLA CONTACT CENTER S.A. - MARÇO 2026 | H10: -32695.94 | I10: -704095.94 | J10: =IF($A10="","",IFERROR(_xlfn.XLOOKUP($E10,noverdefornecedor!$A:$A,noverdefornecedor!$B:$B),"")) -> PARLA CONTACT CENTER S.A. | K10: =IF($A10="","",IFERROR(_xlfn.XLOOKUP($F10,noverdepacote!$A:$A,noverdepacote!$D:$D),"")) -> CRM & Call Center | L10: =IF($A10="","",DATE(YEAR($A10),MONTH($A10),1)) -> 46082 | M10: =IF($A10="","","Noverde") -> Noverde | N10: =IF($A10="","",IFERROR(_xlfn.XLOOKUP($F10,noverdepacote!$A:$A,noverdepacote!$B:$B),"")) -> Call Center
A11: 46112 | B11: 19672 | C11: LC | D11: 19672 | E11: F000145 | F11: 81763005005 | G11: PROV. PONTAL SERVICOS EM COMUNICACAO DIGITAL LTDA - mar/26 | H11: -250000 | I11: -954095.94 | J11: =IF($A11="","",IFERROR(_xlfn.XLOOKUP($E11,noverdefornecedor!$A:$A,noverdefornecedor!$B:$B),"")) -> PONTAL SERVICOS EM COMUNICACAO DIGITAL LTDA | K11: =IF($A11="","",IFERROR(_xlfn.XLOOKUP($F11,noverdepacote!$A:$A,noverdepacote!$D:$D),"")) -> Other costs - NoVerde | L11: =IF($A11="","",DATE(YEAR($A11),MONTH($A11),1)) -> 46082 | M11: =IF($A11="","","Noverde") -> Noverde | N11: =IF($A11="","",IFERROR(_xlfn.XLOOKUP($F11,noverdepacote!$A:$A,noverdepacote!$B:$B),"")) -> Custo de Cobrança (Custo)
A12: 46142 | B12: 20161 | C12: LC | D12: 20161 | E12: F000034 | F12: 81763005006 | G12: PROV BOA VISTA SERVICOS S.A. - F000034 | H12: -250000 | I12: -1204095.9 | J12: =IF($A12="","",IFERROR(_xlfn.XLOOKUP($E12,noverdefornecedor!$A:$A,noverdefornecedor!$B:$B),"")) -> BOA VISTA SERVICOS S.A. | K12: =IF($A12="","",IFERROR(_xlfn.XLOOKUP($F12,noverdepacote!$A:$A,noverdepacote!$D:$D),"")) -> Other costs - NoVerde | L12: =IF($A12="","",DATE(YEAR($A12),MONTH($A12),1)) -> 46113 | M12: =IF($A12="","","Noverde") -> Noverde | N12: =IF($A12="","",IFERROR(_xlfn.XLOOKUP($F12,noverdepacote!$A:$A,noverdepacote!$B:$B),"")) -> Custos de Credito
A13: 46142 | B13: 20177 | C13: LC | D13: 20177 | E13: F000159 | F13: 81763005005 | G13: PROV NEGOCIE AGORA SERVIÇOS E COBRANÇA LTDA - F000159 | H13: -5400 | I13: -1209495.9 | J13: =IF($A13="","",IFERROR(_xlfn.XLOOKUP($E13,noverdefornecedor!$A:$A,noverdefornecedor!$B:$B),"")) -> NEGOCIE AGORA SERVIÇOS E COBRANÇA LTDA | K13: =IF($A13="","",IFERROR(_xlfn.XLOOKUP($F13,noverdepacote!$A:$A,noverdepacote!$D:$D),"")) -> Other costs - NoVerde | L13: =IF($A13="","",DATE(YEAR($A13),MONTH($A13),1)) -> 46113 | M13: =IF($A13="","","Noverde") -> Noverde | N13: =IF($A13="","",IFERROR(_xlfn.XLOOKUP($F13,noverdepacote!$A:$A,noverdepacote!$B:$B),"")) -> Custo de Cobrança (Custo)
A14: 46142 | B14: 20181 | C14: LC | D14: 20181 | E14: F000029 | F14: 81763005007 | G14: PROV CLEAR SALE S.A. - F000029 | H14: -23000 | I14: -1232495.9 | J14: =IF($A14="","",IFERROR(_xlfn.XLOOKUP($E14,noverdefornecedor!$A:$A,noverdefornecedor!$B:$B),"")) -> CLEAR SALE S.A. | K14: =IF($A14="","",IFERROR(_xlfn.XLOOKUP($F14,noverdepacote!$A:$A,noverdepacote!$D:$D),"")) -> Other costs - NoVerde | L14: =IF($A14="","",DATE(YEAR($A14),MONTH($A14),1)) -> 46113 | M14: =IF($A14="","","Noverde") -> Noverde | N14: =IF($A14="","",IFERROR(_xlfn.XLOOKUP($F14,noverdepacote!$A:$A,noverdepacote!$B:$B),"")) -> Custo De Prevenção de Fraudes
... A36: 46173 | B36: 20769 | C36: LC | D36: 20769 | E36: LC00009 | F36: 81999006002 | G36: Recompra de Carteira FIDC - PERDA OPERACIONAL | H36: -600000 | I36: -4192101.4 | J36: =IF($A36="","",IFERROR(_xlfn.XLOOKUP($E36,noverdefornecedor!$A:$A,noverdefornecedor!$B:$B),"")) -> FIDC - PERDA OPERACIONAL | K36: =IF($A36="","",IFERROR(_xlfn.XLOOKUP($F36,noverdepacote!$A:$A,noverdepacote!$D:$D),"")) -> Financial Losses over Cyber attacks | L36: =IF($A36="","",DATE(YEAR($A36),MONTH($A36),1)) -> 46143 | M36: =IF($A36="","","Noverde") -> Noverde | N36: =IF($A36="","",IFERROR(_xlfn.XLOOKUP($F36,noverdepacote!$A:$A,noverdepacote!$B:$B),"")) -> Perdas Financeiras
J37: =IF($A37="","",IFERROR(_xlfn.XLOOKUP($E37,noverdefornecedor!$A:$A,noverdefornecedor!$B:$B),"")) | K37: =IF($A37="","",IFERROR(_xlfn.XLOOKUP($F37,noverdepacote!$A:$A,noverdepacote!$D:$D),"")) | L37: =IF($A37="","",DATE(YEAR($A37),MONTH($A37),1)) | M37: =IF($A37="","","Noverde") | N37: =IF($A37="","",IFERROR(_xlfn.XLOOKUP($F37,noverdepacote!$A:$A,noverdepacote!$B:$B),""))
J38: =IF($A38="","",IFERROR(_xlfn.XLOOKUP($E38,noverdefornecedor!$A:$A,noverdefornecedor!$B:$B),"")) | K38: =IF($A38="","",IFERROR(_xlfn.XLOOKUP($F38,noverdepacote!$A:$A,noverdepacote!$D:$D),"")) | L38: =IF($A38="","",DATE(YEAR($A38),MONTH($A38),1)) | M38: =IF($A38="","","Noverde") | N38: =IF($A38="","",IFERROR(_xlfn.XLOOKUP($F38,noverdepacote!$A:$A,noverdepacote!$B:$B),""))
J39: =IF($A39="","",IFERROR(_xlfn.XLOOKUP($E39,noverdefornecedor!$A:$A,noverdefornecedor!$B:$B),"")) | K39: =IF($A39="","",IFERROR(_xlfn.XLOOKUP($F39,noverdepacote!$A:$A,noverdepacote!$D:$D),"")) | L39: =IF($A39="","",DATE(YEAR($A39),MONTH($A39),1)) | M39: =IF($A39="","","Noverde") | N39: =IF($A39="","",IFERROR(_xlfn.XLOOKUP($F39,noverdepacote!$A:$A,noverdepacote!$B:$B),""))
J40: =IF($A40="","",IFERROR(_xlfn.XLOOKUP($E40,noverdefornecedor!$A:$A,noverdefornecedor!$B:$B),"")) | K40: =IF($A40="","",IFERROR(_xlfn.XLOOKUP($F40,noverdepacote!$A:$A,noverdepacote!$D:$D),"")) | L40: =IF($A40="","",DATE(YEAR($A40),MONTH($A40),1)) | M40: =IF($A40="","","Noverde") | N40: =IF($A40="","",IFERROR(_xlfn.XLOOKUP($F40,noverdepacote!$A:$A,noverdepacote!$B:$B),""))
J41: =IF($A41="","",IFERROR(_xlfn.XLOOKUP($E41,noverdefornecedor!$A:$A,noverdefornecedor!$B:$B),"")) | K41: =IF($A41="","",IFERROR(_xlfn.XLOOKUP($F41,noverdepacote!$A:$A,noverdepacote!$D:$D),"")) | L41: =IF($A41="","",DATE(YEAR($A41),MONTH($A41),1)) | M41: =IF($A41="","","Noverde") | N41: =IF($A41="","",IFERROR(_xlfn.XLOOKUP($F41,noverdepacote!$A:$A,noverdepacote!$B:$B),""))
J42: =IF($A42="","",IFERROR(_xlfn.XLOOKUP($E42,noverdefornecedor!$A:$A,noverdefornecedor!$B:$B),"")) | K42: =IF($A42="","",IFERROR(_xlfn.XLOOKUP($F42,noverdepacote!$A:$A,noverdepacote!$D:$D),"")) | L42: =IF($A42="","",DATE(YEAR($A42),MONTH($A42),1)) | M42: =IF($A42="","","Noverde") | N42: =IF($A42="","",IFERROR(_xlfn.XLOOKUP($F42,noverdepacote!$A:$A,noverdepacote!$B:$B),""))
J43: =IF($A43="","",IFERROR(_xlfn.XLOOKUP($E43,noverdefornecedor!$A:$A,noverdefornecedor!$B:$B),"")) | K43: =IF($A43="","",IFERROR(_xlfn.XLOOKUP($F43,noverdepacote!$A:$A,noverdepacote!$D:$D),"")) | L43: =IF($A43="","",DATE(YEAR($A43),MONTH($A43),1)) | M43: =IF($A43="","","Noverde") | N43: =IF($A43="","",IFERROR(_xlfn.XLOOKUP($F43,noverdepacote!$A:$A,noverdepacote!$B:$B),""))
J44: =IF($A44="","",IFERROR(_xlfn.XLOOKUP($E44,noverdefornecedor!$A:$A,noverdefornecedor!$B:$B),"")) | K44: =IF($A44="","",IFERROR(_xlfn.XLOOKUP($F44,noverdepacote!$A:$A,noverdepacote!$D:$D),"")) | L44: =IF($A44="","",DATE(YEAR($A44),MONTH($A44),1)) | M44: =IF($A44="","","Noverde") | N44: =IF($A44="","",IFERROR(_xlfn.XLOOKUP($F44,noverdepacote!$A:$A,noverdepacote!$B:$B),""))
J45: =IF($A45="","",IFERROR(_xlfn.XLOOKUP($E45,noverdefornecedor!$A:$A,noverdefornecedor!$B:$B),"")) | K45: =IF($A45="","",IFERROR(_xlfn.XLOOKUP($F45,noverdepacote!$A:$A,noverdepacote!$D:$D),"")) | L45: =IF($A45="","",DATE(YEAR($A45),MONTH($A45),1)) | M45: =IF($A45="","","Noverde") | N45: =IF($A45="","",IFERROR(_xlfn.XLOOKUP($F45,noverdepacote!$A:$A,noverdepacote!$B:$B),""))
J46: =IF($A46="","",IFERROR(_xlfn.XLOOKUP($E46,noverdefornecedor!$A:$A,noverdefornecedor!$B:$B),"")) | K46: =IF($A46="","",IFERROR(_xlfn.XLOOKUP($F46,noverdepacote!$A:$A,noverdepacote!$D:$D),"")) | L46: =IF($A46="","",DATE(YEAR($A46),MONTH($A46),1)) | M46: =IF($A46="","","Noverde") | N46: =IF($A46="","",IFERROR(_xlfn.XLOOKUP($F46,noverdepacote!$A:$A,noverdepacote!$B:$B),""))
J47: =IF($A47="","",IFERROR(_xlfn.XLOOKUP($E47,noverdefornecedor!$A:$A,noverdefornecedor!$B:$B),"")) | K47: =IF($A47="","",IFERROR(_xlfn.XLOOKUP($F47,noverdepacote!$A:$A,noverdepacote!$D:$D),"")) | L47: =IF($A47="","",DATE(YEAR($A47),MONTH($A47),1)) | M47: =IF($A47="","","Noverde") | N47: =IF($A47="","",IFERROR(_xlfn.XLOOKUP($F47,noverdepacote!$A:$A,noverdepacote!$B:$B),""))
J48: =IF($A48="","",IFERROR(_xlfn.XLOOKUP($E48,noverdefornecedor!$A:$A,noverdefornecedor!$B:$B),"")) | K48: =IF($A48="","",IFERROR(_xlfn.XLOOKUP($F48,noverdepacote!$A:$A,noverdepacote!$D:$D),"")) | L48: =IF($A48="","",DATE(YEAR($A48),MONTH($A48),1)) | M48: =IF($A48="","","Noverde") | N48: =IF($A48="","",IFERROR(_xlfn.XLOOKUP($F48,noverdepacote!$A:$A,noverdepacote!$B:$B),""))
... J200: =IF($A200="","",IFERROR(_xlfn.XLOOKUP($E200,noverdefornecedor!$A:$A,noverdefornecedor!$B:$B),"")) | K200: =IF($A200="","",IFERROR(_xlfn.XLOOKUP($F200,noverdepacote!$A:$A,noverdepacote!$D:$D),"")) | L200: =IF($A200="","",DATE(YEAR($A200),MONTH($A200),1)) | M200: =IF($A200="","","Noverde") | N200: =IF($A200="","",IFERROR(_xlfn.XLOOKUP($F200,noverdepacote!$A:$A,noverdepacote!$B:$B),""))

Sheet Dotzprovisões
A1: Data de lançamento | B1: Nº transação | C1: Origem | D1: Nº origem | E1: Ref.3 | F1: Conta de contrapartida | G1: Detalhes | H1: C/D (ML) | I1: Saldo acumulado (MC) | J1: Fornecedor | K1: SubGrupo | L1: Mês/Ano | M1: Empresa | N1: Descrição Conta
C2: SI | I2: 0
A3: 46053 | B3: 15276 | C3: LC | D3: 15276 | E3: F000166 | F3: 3313020 | G3: Provisão Grant Thorton | H3: -34013.61 | I3: -34013.61 | J3: =IF($A3="","",IFERROR(_xlfn.XLOOKUP($E3,dotzfornecedor!$A:$A,dotzfornecedor!$B:$B),"")) -> GRANT THORNTON AUDITORES INDEPENDENTES LTDA | K3: =IF($A3="","",IFERROR(_xlfn.XLOOKUP($F3,dotzpacote!$A:$A,dotzpacote!$D:$D),"")) -> Services | L3: =IF($A3="","",DATE(YEAR($A3),MONTH($A3),1)) -> 46023 | M3: =IF($A3="","","Dotz") -> Dotz | N3: =IF($A3="","",IFERROR(_xlfn.XLOOKUP($F3,dotzpacote!$A:$A,dotzpacote!$B:$B),"")) -> Assessoria Contábil
A4: 46054 | B4: 15573 | C4: LC | D4: 15573 | E4: F000036 | F4: 2111004 | G4: Provisão Pinheiro Guimarães(Estorno) - 15071 | H4: -8449.78 | I4: -42463.39 | J4: =IF($A4="","",IFERROR(_xlfn.XLOOKUP($E4,dotzfornecedor!$A:$A,dotzfornecedor!$B:$B),"")) -> Pinheiro Guimarães | K4: =IF($A4="","",IFERROR(_xlfn.XLOOKUP($F4,dotzpacote!$A:$A,dotzpacote!$D:$D),"")) | L4: =IF($A4="","",DATE(YEAR($A4),MONTH($A4),1)) -> 46054 | M4: =IF($A4="","","Dotz") -> Dotz | N4: =IF($A4="","",IFERROR(_xlfn.XLOOKUP($F4,dotzpacote!$A:$A,dotzpacote!$B:$B),""))
A5: 46081 | B5: 15453 | C5: LC | D5: 15453 | E5: F000166 | F5: 3313020 | G5: Provisão Grant Thorton | H5: -34013.61 | I5: -76477 | J5: =IF($A5="","",IFERROR(_xlfn.XLOOKUP($E5,dotzfornecedor!$A:$A,dotzfornecedor!$B:$B),"")) -> GRANT THORNTON AUDITORES INDEPENDENTES LTDA | K5: =IF($A5="","",IFERROR(_xlfn.XLOOKUP($F5,dotzpacote!$A:$A,dotzpacote!$D:$D),"")) -> Services | L5: =IF($A5="","",DATE(YEAR($A5),MONTH($A5),1)) -> 46054 | M5: =IF($A5="","","Dotz") -> Dotz | N5: =IF($A5="","",IFERROR(_xlfn.XLOOKUP($F5,dotzpacote!$A:$A,dotzpacote!$B:$B),"")) -> Assessoria Contábil
A6: 46112 | B6: 15996 | C6: LC | D6: 15996 | E6: F000166 | F6: 3313020 | G6: Provisão Grant Thorton | H6: -34013.61 | I6: -110490.61 | J6: =IF($A6="","",IFERROR(_xlfn.XLOOKUP($E6,dotzfornecedor!$A:$A,dotzfornecedor!$B:$B),"")) -> GRANT THORNTON AUDITORES INDEPENDENTES LTDA | K6: =IF($A6="","",IFERROR(_xlfn.XLOOKUP($F6,dotzpacote!$A:$A,dotzpacote!$D:$D),"")) -> Services | L6: =IF($A6="","",DATE(YEAR($A6),MONTH($A6),1)) -> 46082 | M6: =IF($A6="","","Dotz") -> Dotz | N6: =IF($A6="","",IFERROR(_xlfn.XLOOKUP($F6,dotzpacote!$A:$A,dotzpacote!$B:$B),"")) -> Assessoria Contábil
A7: 46142 | B7: 16363 | C7: LC | D7: 16363 | E7: F000165 | F7: 3313350 | G7: Provisão nf HeidrickRecrutamento Especializado - F000165 | H7: -61980.91 | I7: -172471.52 | J7: =IF($A7="","",IFERROR(_xlfn.XLOOKUP($E7,dotzfornecedor!$A:$A,dotzfornecedor!$B:$B),"")) -> HEIDRICK & STRUGGLES RECRUTAMENTO ESPECIALIZADO LTDA. | K7: =IF($A7="","",IFERROR(_xlfn.XLOOKUP($F7,dotzpacote!$A:$A,dotzpacote!$D:$D),"")) -> Services | L7: =IF($A7="","",DATE(YEAR($A7),MONTH($A7),1)) -> 46113 | M7: =IF($A7="","","Dotz") -> Dotz | N7: =IF($A7="","",IFERROR(_xlfn.XLOOKUP($F7,dotzpacote!$A:$A,dotzpacote!$B:$B),"")) -> Serviços de Consultoria
A8: 46171 | B8: 16774 | C8: LC | D8: 16774 | E8: F000103 | F8: 3313030 | G8: Provisão NF Mello e Torres - F000103 | H8: -41743.92 | I8: -214215.44 | J8: =IF($A8="","",IFERROR(_xlfn.XLOOKUP($E8,dotzfornecedor!$A:$A,dotzfornecedor!$B:$B),"")) -> Mello e Torres Sociedade de Advogados | K8: =IF($A8="","",IFERROR(_xlfn.XLOOKUP($F8,dotzpacote!$A:$A,dotzpacote!$D:$D),"")) -> Services | L8: =IF($A8="","",DATE(YEAR($A8),MONTH($A8),1)) -> 46143 | M8: =IF($A8="","","Dotz") -> Dotz | N8: =IF($A8="","",IFERROR(_xlfn.XLOOKUP($F8,dotzpacote!$A:$A,dotzpacote!$B:$B),"")) -> Assessoria Jurídica
A9: 46171 | B9: 16775 | C9: LC | D9: 16775 | E9: F000165 | F9: 3313350 | G9: Provisão nf HeidrickRecrutamento Especializado - F000165 | H9: -61980.91 | I9: -276196.35 | J9: =IF($A9="","",IFERROR(_xlfn.XLOOKUP($E9,dotzfornecedor!$A:$A,dotzfornecedor!$B:$B),"")) -> HEIDRICK & STRUGGLES RECRUTAMENTO ESPECIALIZADO LTDA. | K9: =IF($A9="","",IFERROR(_xlfn.XLOOKUP($F9,dotzpacote!$A:$A,dotzpacote!$D:$D),"")) -> Services | L9: =IF($A9="","",DATE(YEAR($A9),MONTH($A9),1)) -> 46143 | M9: =IF($A9="","","Dotz") -> Dotz | N9: =IF($A9="","",IFERROR(_xlfn.XLOOKUP($F9,dotzpacote!$A:$A,dotzpacote!$B:$B),"")) -> Serviços de Consultoria
A10: 46171 | B10: 16809 | C10: LC | D10: 16809 | E10: F000166 | F10: 3313020 | G10: Provisão Grant Thorton | H10: -34013.61 | I10: -310209.96 | J10: =IF($A10="","",IFERROR(_xlfn.XLOOKUP($E10,dotzfornecedor!$A:$A,dotzfornecedor!$B:$B),"")) -> GRANT THORNTON AUDITORES INDEPENDENTES LTDA | K10: =IF($A10="","",IFERROR(_xlfn.XLOOKUP($F10,dotzpacote!$A:$A,dotzpacote!$D:$D),"")) -> Services | L10: =IF($A10="","",DATE(YEAR($A10),MONTH($A10),1)) -> 46143 | M10: =IF($A10="","","Dotz") -> Dotz | N10: =IF($A10="","",IFERROR(_xlfn.XLOOKUP($F10,dotzpacote!$A:$A,dotzpacote!$B:$B),"")) -> Assessoria Contábil
A11: 46171 | B11: 16818 | C11: LC | D11: 16818 | E11: F000023 | F11: 3313350 | G11: Prov. Amortização Action Syst | H11: -9576.28 | I11: -319786.24 | J11: =IF($A11="","",IFERROR(_xlfn.XLOOKUP($E11,dotzfornecedor!$A:$A,dotzfornecedor!$B:$B),"")) -> ACTION SYSTEMS SERVICOS EM INFORMATICA LTDA | K11: =IF($A11="","",IFERROR(_xlfn.XLOOKUP($F11,dotzpacote!$A:$A,dotzpacote!$D:$D),"")) -> Services | L11: =IF($A11="","",DATE(YEAR($A11),MONTH($A11),1)) -> 46143 | M11: =IF($A11="","","Dotz") -> Dotz | N11: =IF($A11="","",IFERROR(_xlfn.XLOOKUP($F11,dotzpacote!$A:$A,dotzpacote!$B:$B),"")) -> Serviços de Consultoria
A12: 46171 | B12: 16819 | C12: LC | D12: 16819 | E12: F000071 | F12: 3313270 | G12: PROV. INVENT SOFTWARE LTDA | H12: -18750 | I12: -338536.24 | J12: =IF($A12="","",IFERROR(_xlfn.XLOOKUP($E12,dotzfornecedor!$A:$A,dotzfornecedor!$B:$B),"")) -> INVENT SOFTWARE LTDA | K12: =IF($A12="","",IFERROR(_xlfn.XLOOKUP($F12,dotzpacote!$A:$A,dotzpacote!$D:$D),"")) -> IT & Telecom | L12: =IF($A12="","",DATE(YEAR($A12),MONTH($A12),1)) -> 46143 | M12: =IF($A12="","","Dotz") -> Dotz | N12: =IF($A12="","",IFERROR(_xlfn.XLOOKUP($F12,dotzpacote!$A:$A,dotzpacote!$B:$B),"")) -> Licenças
A13: 46172 | B13: 16745 | C13: LC | D13: 16745 | E13: F000163 | F13: 3313030 | G13: Provisão MMF e A&M Créditos Previdenciários | H13: -21404.25 | I13: -359940.49 | J13: =IF($A13="","",IFERROR(_xlfn.XLOOKUP($E13,dotzfornecedor!$A:$A,dotzfornecedor!$B:$B),"")) -> MOSS, MUZZI, FALCAO, MASSOTE E WERNECK ADVOGADOS ASSOCIADOS | K13: =IF($A13="","",IFERROR(_xlfn.XLOOKUP($F13,dotzpacote!$A:$A,dotzpacote!$D:$D),"")) -> Services | L13: =IF($A13="","",DATE(YEAR($A13),MONTH($A13),1)) -> 46143 | M13: =IF($A13="","","Dotz") -> Dotz | N13: =IF($A13="","",IFERROR(_xlfn.XLOOKUP($F13,dotzpacote!$A:$A,dotzpacote!$B:$B),"")) -> Assessoria Jurídica
J14: =IF($A14="","",IFERROR(_xlfn.XLOOKUP($E14,dotzfornecedor!$A:$A,dotzfornecedor!$B:$B),"")) | K14: =IF($A14="","",IFERROR(_xlfn.XLOOKUP($F14,dotzpacote!$A:$A,dotzpacote!$D:$D),"")) | L14: =IF($A14="","",DATE(YEAR($A14),MONTH($A14),1)) | M14: =IF($A14="","","Dotz") | N14: =IF($A14="","",IFERROR(_xlfn.XLOOKUP($F14,dotzpacote!$A:$A,dotzpacote!$B:$B),""))
J15: =IF($A15="","",IFERROR(_xlfn.XLOOKUP($E15,dotzfornecedor!$A:$A,dotzfornecedor!$B:$B),"")) | K15: =IF($A15="","",IFERROR(_xlfn.XLOOKUP($F15,dotzpacote!$A:$A,dotzpacote!$D:$D),"")) | L15: =IF($A15="","",DATE(YEAR($A15),MONTH($A15),1)) | M15: =IF($A15="","","Dotz") | N15: =IF($A15="","",IFERROR(_xlfn.XLOOKUP($F15,dotzpacote!$A:$A,dotzpacote!$B:$B),""))
J16: =IF($A16="","",IFERROR(_xlfn.XLOOKUP($E16,dotzfornecedor!$A:$A,dotzfornecedor!$B:$B),"")) | K16: =IF($A16="","",IFERROR(_xlfn.XLOOKUP($F16,dotzpacote!$A:$A,dotzpacote!$D:$D),"")) | L16: =IF($A16="","",DATE(YEAR($A16),MONTH($A16),1)) | M16: =IF($A16="","","Dotz") | N16: =IF($A16="","",IFERROR(_xlfn.XLOOKUP($F16,dotzpacote!$A:$A,dotzpacote!$B:$B),""))
J17: =IF($A17="","",IFERROR(_xlfn.XLOOKUP($E17,dotzfornecedor!$A:$A,dotzfornecedor!$B:$B),"")) | K17: =IF($A17="","",IFERROR(_xlfn.XLOOKUP($F17,dotzpacote!$A:$A,dotzpacote!$D:$D),"")) | L17: =IF($A17="","",DATE(YEAR($A17),MONTH($A17),1)) | M17: =IF($A17="","","Dotz") | N17: =IF($A17="","",IFERROR(_xlfn.XLOOKUP($F17,dotzpacote!$A:$A,dotzpacote!$B:$B),""))
J18: =IF($A18="","",IFERROR(_xlfn.XLOOKUP($E18,dotzfornecedor!$A:$A,dotzfornecedor!$B:$B),"")) | K18: =IF($A18="","",IFERROR(_xlfn.XLOOKUP($F18,dotzpacote!$A:$A,dotzpacote!$D:$D),"")) | L18: =IF($A18="","",DATE(YEAR($A18),MONTH($A18),1)) | M18: =IF($A18="","","Dotz") | N18: =IF($A18="","",IFERROR(_xlfn.XLOOKUP($F18,dotzpacote!$A:$A,dotzpacote!$B:$B),""))
J19: =IF($A19="","",IFERROR(_xlfn.XLOOKUP($E19,dotzfornecedor!$A:$A,dotzfornecedor!$B:$B),"")) | K19: =IF($A19="","",IFERROR(_xlfn.XLOOKUP($F19,dotzpacote!$A:$A,dotzpacote!$D:$D),"")) | L19: =IF($A19="","",DATE(YEAR($A19),MONTH($A19),1)) | M19: =IF($A19="","","Dotz") | N19: =IF($A19="","",IFERROR(_xlfn.XLOOKUP($F19,dotzpacote!$A:$A,dotzpacote!$B:$B),""))
J20: =IF($A20="","",IFERROR(_xlfn.XLOOKUP($E20,dotzfornecedor!$A:$A,dotzfornecedor!$B:$B),"")) | K20: =IF($A20="","",IFERROR(_xlfn.XLOOKUP($F20,dotzpacote!$A:$A,dotzpacote!$D:$D),"")) | L20: =IF($A20="","",DATE(YEAR($A20),MONTH($A20),1)) | M20: =IF($A20="","","Dotz") | N20: =IF($A20="","",IFERROR(_xlfn.XLOOKUP($F20,dotzpacote!$A:$A,dotzpacote!$B:$B),""))
J21: =IF($A21="","",IFERROR(_xlfn.XLOOKUP($E21,dotzfornecedor!$A:$A,dotzfornecedor!$B:$B),"")) | K21: =IF($A21="","",IFERROR(_xlfn.XLOOKUP($F21,dotzpacote!$A:$A,dotzpacote!$D:$D),"")) | L21: =IF($A21="","",DATE(YEAR($A21),MONTH($A21),1)) | M21: =IF($A21="","","Dotz") | N21: =IF($A21="","",IFERROR(_xlfn.XLOOKUP($F21,dotzpacote!$A:$A,dotzpacote!$B:$B),""))
J22: =IF($A22="","",IFERROR(_xlfn.XLOOKUP($E22,dotzfornecedor!$A:$A,dotzfornecedor!$B:$B),"")) | K22: =IF($A22="","",IFERROR(_xlfn.XLOOKUP($F22,dotzpacote!$A:$A,dotzpacote!$D:$D),"")) | L22: =IF($A22="","",DATE(YEAR($A22),MONTH($A22),1)) | M22: =IF($A22="","","Dotz") | N22: =IF($A22="","",IFERROR(_xlfn.XLOOKUP($F22,dotzpacote!$A:$A,dotzpacote!$B:$B),""))
J23: =IF($A23="","",IFERROR(_xlfn.XLOOKUP($E23,dotzfornecedor!$A:$A,dotzfornecedor!$B:$B),"")) | K23: =IF($A23="","",IFERROR(_xlfn.XLOOKUP($F23,dotzpacote!$A:$A,dotzpacote!$D:$D),"")) | L23: =IF($A23="","",DATE(YEAR($A23),MONTH($A23),1)) | M23: =IF($A23="","","Dotz") | N23: =IF($A23="","",IFERROR(_xlfn.XLOOKUP($F23,dotzpacote!$A:$A,dotzpacote!$B:$B),""))
J24: =IF($A24="","",IFERROR(_xlfn.XLOOKUP($E24,dotzfornecedor!$A:$A,dotzfornecedor!$B:$B),"")) | K24: =IF($A24="","",IFERROR(_xlfn.XLOOKUP($F24,dotzpacote!$A:$A,dotzpacote!$D:$D),"")) | L24: =IF($A24="","",DATE(YEAR($A24),MONTH($A24),1)) | M24: =IF($A24="","","Dotz") | N24: =IF($A24="","",IFERROR(_xlfn.XLOOKUP($F24,dotzpacote!$A:$A,dotzpacote!$B:$B),""))
J25: =IF($A25="","",IFERROR(_xlfn.XLOOKUP($E25,dotzfornecedor!$A:$A,dotzfornecedor!$B:$B),"")) | K25: =IF($A25="","",IFERROR(_xlfn.XLOOKUP($F25,dotzpacote!$A:$A,dotzpacote!$D:$D),"")) | L25: =IF($A25="","",DATE(YEAR($A25),MONTH($A25),1)) | M25: =IF($A25="","","Dotz") | N25: =IF($A25="","",IFERROR(_xlfn.XLOOKUP($F25,dotzpacote!$A:$A,dotzpacote!$B:$B),""))
... J200: =IF($A200="","",IFERROR(_xlfn.XLOOKUP($E200,dotzfornecedor!$A:$A,dotzfornecedor!$B:$B),"")) | K200: =IF($A200="","",IFERROR(_xlfn.XLOOKUP($F200,dotzpacote!$A:$A,dotzpacote!$D:$D),"")) | L200: =IF($A200="","",DATE(YEAR($A200),MONTH($A200),1)) | M200: =IF($A200="","","Dotz") | N200: =IF($A200="","",IFERROR(_xlfn.XLOOKUP($F200,dotzpacote!$A:$A,dotzpacote!$B:$B),""))

Sheet PAYprovisões
A1: Data de lançamento | B1: Nº transação | C1: Origem | D1: Nº origem | E1: Ref.3 | F1: Conta de contrapartida | G1: Detalhes | H1: C/D (ML) | I1: Saldo acumulado (MC) | J1: Fornecedor | K1: SubGrupo | L1: Mês/Ano | M1: Empresa | N1: Descrição Conta
C2: SI | I2: 0
A3: 46080 | B3: 43065 | C3: LC | D3: 43065 | E3: F000119 | F3: 81763005002 | G3: Provisão Grant Thorton | H3: -5833.33 | I3: -5833.33 | J3: =IF($A3="","",IFERROR(_xlfn.XLOOKUP($E3,payfornecedor!$A:$A,payfornecedor!$B:$B),"")) -> GRANT THORNTON AUDITORES INDEPENDENTES LTDA | K3: =IF($A3="","",IFERROR(_xlfn.XLOOKUP($F3,paypacote!$A:$A,paypacote!$D:$D),"")) -> Services | L3: =IF($A3="","",DATE(YEAR($A3),MONTH($A3),1)) -> 46054 | M3: =IF($A3="","","PAY") -> PAY | N3: =IF($A3="","",IFERROR(_xlfn.XLOOKUP($F3,paypacote!$A:$A,paypacote!$B:$B),"")) -> Assessoria Contábil e Auditoria
A4: 46112 | B4: 43819 | C4: LC | D4: 43819 | E4: F000119 | F4: 81763005002 | G4: Provisão Grant Thorton | H4: -5833.33 | I4: -11666.66 | J4: =IF($A4="","",IFERROR(_xlfn.XLOOKUP($E4,payfornecedor!$A:$A,payfornecedor!$B:$B),"")) -> GRANT THORNTON AUDITORES INDEPENDENTES LTDA | K4: =IF($A4="","",IFERROR(_xlfn.XLOOKUP($F4,paypacote!$A:$A,paypacote!$D:$D),"")) -> Services | L4: =IF($A4="","",DATE(YEAR($A4),MONTH($A4),1)) -> 46082 | M4: =IF($A4="","","PAY") -> PAY | N4: =IF($A4="","",IFERROR(_xlfn.XLOOKUP($F4,paypacote!$A:$A,paypacote!$B:$B),"")) -> Assessoria Contábil e Auditoria
A5: 46113 | B5: 44280 | C5: LC | D5: 44280 | E5: F000119 | F5: 81763005002 | G5: Provisão Grant Thorton | H5: -5833.33 | I5: -17499.99 | J5: =IF($A5="","",IFERROR(_xlfn.XLOOKUP($E5,payfornecedor!$A:$A,payfornecedor!$B:$B),"")) -> GRANT THORNTON AUDITORES INDEPENDENTES LTDA | K5: =IF($A5="","",IFERROR(_xlfn.XLOOKUP($F5,paypacote!$A:$A,paypacote!$D:$D),"")) -> Services | L5: =IF($A5="","",DATE(YEAR($A5),MONTH($A5),1)) -> 46113 | M5: =IF($A5="","","PAY") -> PAY | N5: =IF($A5="","",IFERROR(_xlfn.XLOOKUP($F5,paypacote!$A:$A,paypacote!$B:$B),"")) -> Assessoria Contábil e Auditoria
A6: 46171 | B6: 44823 | C6: LC | D6: 44823 | E6: F000072 | F6: 81739008007 | G6: Provisão NF TPZ soluções - F000072 | H6: -57307 | I6: -74806.99 | J6: =IF($A6="","",IFERROR(_xlfn.XLOOKUP($E6,payfornecedor!$A:$A,payfornecedor!$B:$B),"")) -> TPZ SOLUCOES DIGITAIS LTDA. | K6: =IF($A6="","",IFERROR(_xlfn.XLOOKUP($F6,paypacote!$A:$A,paypacote!$D:$D),"")) -> Other costs - Dotz Pay | L6: =IF($A6="","",DATE(YEAR($A6),MONTH($A6),1)) -> 46143 | M6: =IF($A6="","","PAY") -> PAY | N6: =IF($A6="","",IFERROR(_xlfn.XLOOKUP($F6,paypacote!$A:$A,paypacote!$B:$B),"")) -> Onboarding
J7: =IF($A7="","",IFERROR(_xlfn.XLOOKUP($E7,payfornecedor!$A:$A,payfornecedor!$B:$B),"")) | K7: =IF($A7="","",IFERROR(_xlfn.XLOOKUP($F7,paypacote!$A:$A,paypacote!$D:$D),"")) | L7: =IF($A7="","",DATE(YEAR($A7),MONTH($A7),1)) | M7: =IF($A7="","","PAY") | N7: =IF($A7="","",IFERROR(_xlfn.XLOOKUP($F7,paypacote!$A:$A,paypacote!$B:$B),""))
J8: =IF($A8="","",IFERROR(_xlfn.XLOOKUP($E8,payfornecedor!$A:$A,payfornecedor!$B:$B),"")) | K8: =IF($A8="","",IFERROR(_xlfn.XLOOKUP($F8,paypacote!$A:$A,paypacote!$D:$D),"")) | L8: =IF($A8="","",DATE(YEAR($A8),MONTH($A8),1)) | M8: =IF($A8="","","PAY") | N8: =IF($A8="","",IFERROR(_xlfn.XLOOKUP($F8,paypacote!$A:$A,paypacote!$B:$B),""))
J9: =IF($A9="","",IFERROR(_xlfn.XLOOKUP($E9,payfornecedor!$A:$A,payfornecedor!$B:$B),"")) | K9: =IF($A9="","",IFERROR(_xlfn.XLOOKUP($F9,paypacote!$A:$A,paypacote!$D:$D),"")) | L9: =IF($A9="","",DATE(YEAR($A9),MONTH($A9),1)) | M9: =IF($A9="","","PAY") | N9: =IF($A9="","",IFERROR(_xlfn.XLOOKUP($F9,paypacote!$A:$A,paypacote!$B:$B),""))
J10: =IF($A10="","",IFERROR(_xlfn.XLOOKUP($E10,payfornecedor!$A:$A,payfornecedor!$B:$B),"")) | K10: =IF($A10="","",IFERROR(_xlfn.XLOOKUP($F10,paypacote!$A:$A,paypacote!$D:$D),"")) | L10: =IF($A10="","",DATE(YEAR($A10),MONTH($A10),1)) | M10: =IF($A10="","","PAY") | N10: =IF($A10="","",IFERROR(_xlfn.XLOOKUP($F10,paypacote!$A:$A,paypacote!$B:$B),""))
J11: =IF($A11="","",IFERROR(_xlfn.XLOOKUP($E11,payfornecedor!$A:$A,payfornecedor!$B:$B),"")) | K11: =IF($A11="","",IFERROR(_xlfn.XLOOKUP($F11,paypacote!$A:$A,paypacote!$D:$D),"")) | L11: =IF($A11="","",DATE(YEAR($A11),MONTH($A11),1)) | M11: =IF($A11="","","PAY") | N11: =IF($A11="","",IFERROR(_xlfn.XLOOKUP($F11,paypacote!$A:$A,paypacote!$B:$B),""))
J12: =IF($A12="","",IFERROR(_xlfn.XLOOKUP($E12,payfornecedor!$A:$A,payfornecedor!$B:$B),"")) | K12: =IF($A12="","",IFERROR(_xlfn.XLOOKUP($F12,paypacote!$A:$A,paypacote!$D:$D),"")) | L12: =IF($A12="","",DATE(YEAR($A12),MONTH($A12),1)) | M12: =IF($A12="","","PAY") | N12: =IF($A12="","",IFERROR(_xlfn.XLOOKUP($F12,paypacote!$A:$A,paypacote!$B:$B),""))
J13: =IF($A13="","",IFERROR(_xlfn.XLOOKUP($E13,payfornecedor!$A:$A,payfornecedor!$B:$B),"")) | K13: =IF($A13="","",IFERROR(_xlfn.XLOOKUP($F13,paypacote!$A:$A,paypacote!$D:$D),"")) | L13: =IF($A13="","",DATE(YEAR($A13),MONTH($A13),1)) | M13: =IF($A13="","","PAY") | N13: =IF($A13="","",IFERROR(_xlfn.XLOOKUP($F13,paypacote!$A:$A,paypacote!$B:$B),""))
J14: =IF($A14="","",IFERROR(_xlfn.XLOOKUP($E14,payfornecedor!$A:$A,payfornecedor!$B:$B),"")) | K14: =IF($A14="","",IFERROR(_xlfn.XLOOKUP($F14,paypacote!$A:$A,paypacote!$D:$D),"")) | L14: =IF($A14="","",DATE(YEAR($A14),MONTH($A14),1)) | M14: =IF($A14="","","PAY") | N14: =IF($A14="","",IFERROR(_xlfn.XLOOKUP($F14,paypacote!$A:$A,paypacote!$B:$B),""))
J15: =IF($A15="","",IFERROR(_xlfn.XLOOKUP($E15,payfornecedor!$A:$A,payfornecedor!$B:$B),"")) | K15: =IF($A15="","",IFERROR(_xlfn.XLOOKUP($F15,paypacote!$A:$A,paypacote!$D:$D),"")) | L15: =IF($A15="","",DATE(YEAR($A15),MONTH($A15),1)) | M15: =IF($A15="","","PAY") | N15: =IF($A15="","",IFERROR(_xlfn.XLOOKUP($F15,paypacote!$A:$A,paypacote!$B:$B),""))
J16: =IF($A16="","",IFERROR(_xlfn.XLOOKUP($E16,payfornecedor!$A:$A,payfornecedor!$B:$B),"")) | K16: =IF($A16="","",IFERROR(_xlfn.XLOOKUP($F16,paypacote!$A:$A,paypacote!$D:$D),"")) | L16: =IF($A16="","",DATE(YEAR($A16),MONTH($A16),1)) | M16: =IF($A16="","","PAY") | N16: =IF($A16="","",IFERROR(_xlfn.XLOOKUP($F16,paypacote!$A:$A,paypacote!$B:$B),""))
J17: =IF($A17="","",IFERROR(_xlfn.XLOOKUP($E17,payfornecedor!$A:$A,payfornecedor!$B:$B),"")) | K17: =IF($A17="","",IFERROR(_xlfn.XLOOKUP($F17,paypacote!$A:$A,paypacote!$D:$D),"")) | L17: =IF($A17="","",DATE(YEAR($A17),MONTH($A17),1)) | M17: =IF($A17="","","PAY") | N17: =IF($A17="","",IFERROR(_xlfn.XLOOKUP($F17,paypacote!$A:$A,paypacote!$B:$B),""))
J18: =IF($A18="","",IFERROR(_xlfn.XLOOKUP($E18,payfornecedor!$A:$A,payfornecedor!$B:$B),"")) | K18: =IF($A18="","",IFERROR(_xlfn.XLOOKUP($F18,paypacote!$A:$A,paypacote!$D:$D),"")) | L18: =IF($A18="","",DATE(YEAR($A18),MONTH($A18),1)) | M18: =IF($A18="","","PAY") | N18: =IF($A18="","",IFERROR(_xlfn.XLOOKUP($F18,paypacote!$A:$A,paypacote!$B:$B),""))
... J200: =IF($A200="","",IFERROR(_xlfn.XLOOKUP($E200,payfornecedor!$A:$A,payfornecedor!$B:$B),"")) | K200: =IF($A200="","",IFERROR(_xlfn.XLOOKUP($F200,paypacote!$A:$A,paypacote!$D:$D),"")) | L200: =IF($A200="","",DATE(YEAR($A200),MONTH($A200),1)) | M200: =IF($A200="","","PAY") | N200: =IF($A200="","",IFERROR(_xlfn.XLOOKUP($F200,paypacote!$A:$A,paypacote!$B:$B),""))

Sheet cbsmpacote
A1: Conta | B1: Descrção | C1: Grupo | D1: SubGrupo
B2: Net Revenues
B3: Gross Revenues
B4: Spread
A5: 3111152 | B5: Receita de Venda de Dotz - Clube Dotz | C5: Gross Revenues | D5: Spread
A6: 3111150 | B6: Receita de Venda de Dotz - Non Split Fee | C6: Gross Revenues | D6: Spread
A7: 3111154 | B7: Receita de Venda de Dotz - Pré-Pago | C7: Gross Revenues | D7: Spread
B8: TOTAL DE AJUSTES
B9: Redemption
A10: 3111171 | B10: Receita de Resgate de Dotz - Completa Dotz | C10: Gross Revenues | D10: Redemption
A11: 3111174 | B11: Receita de Resgate de Dotz - Pré-Pago | C11: Gross Revenues | D11: Redemption
A12: 3111172 | B12: Receita de Resgate de Dotz - Clube Dotz | C12: Gross Revenues | D12: Redemption
A13: 3111170 | B13: Receita de Resgate de Dotz - Non Split Fee | C13: Gross Revenues | D13: Redemption
A14: 3111160 | B14: Receita de Resgate de Dotz - Split Fee e Projetos Especiais | C14: Gross Revenues | D14: Redemption
A15: 3111199 | B15: Receita de Resgate de Dotz a Faturar | C15: Gross Revenues | D15: Redemption
A16: 3111173 | B16: Receita de Resgate de Dotz - Viaja | C16: Gross Revenues | D16: Redemption
B17: TOTAL DE AJUSTES
B18: Breakage
A19: 3111451 | B19: Receita de Expiração de Dotz - Completa Dotz | C19: Gross Revenues | D19: Breakage
A20: 3113100 | B20: Projeto Franquia - Receita de Venda de Dotz - Non Split Fee | C20: Gross Revenues | D20: Breakage
A21: 3111450 | B21: Receita de Expiração de Dotz - Non Split Fee | C21: Gross Revenues | D21: Breakage
A22: 3113101 | B22: Projeto Franquia - Receita de Expiração de Dotz - Non Split Fee | C22: Gross Revenues | D22: Breakage
A23: 3111452 | B23: Receita de Expiração de Dotz - Clube Dotz | C23: Gross Revenues | D23: Breakage
A24: 3111454 | B24: Receita de Expiração de Dotz - Pré-Pago | C24: Gross Revenues | D24: Breakage
B25: TOTAL DE AJUSTES
B26: Service Revenues
B27: Fee
A28: 3111300 | B28: Receita Serviços de Marketing | C28: Service Revenues | D28: Fee
A29: 3111200 | B29: Receita Serviços - Comissão | C29: Service Revenues | D29: Fee
B30: TOTAL DE AJUSTES
B31: Service Revenues - Dotz Pay
B32: TOTAL DE AJUSTES
B33: Service Revenues - Noverde
B34: TOTAL DE AJUSTES
B35: (-) Sales Tax & Deductions
B36: Pis
A37: 3131200 | B37: Pis - Serviços Prestados | C37: (-) Sales Tax & Deductions | D37: Sales Tax
A38: 3131110 | B38: Pis - Vendas | C38: (-) Sales Tax & Deductions | D38: Sales Tax
B39: TOTAL DE AJUSTES
B40: Cofins
...

Sheet dotzpacote
A1: Conta | B1: Descrção | C1: Grupo | D1: SubGrupo
B2: Net Revenues
B3: Gross Revenues
B4: Spread
B5: TOTAL DE AJUSTES
B6: Redemption
B7: TOTAL DE AJUSTES
B8: Breakage
B9: TOTAL DE AJUSTES
B10: Service Revenues
B11: Fee
B12: TOTAL DE AJUSTES
B13: Service Revenues - Dotz Pay
... B18: Pis
A19: 3131110 | B19: Pis - Vendas | C19: (-) Sales Tax & Deductions | D19: Sales Tax
B20: TOTAL DE AJUSTES
B21: Cofins
A22: 3131120 | B22: Cofins - Vendas | C22: (-) Sales Tax & Deductions | D22: Sales Tax
B23: TOTAL DE AJUSTES
B24: ISS
B25: TOTAL DE AJUSTES
B26: Deductions
B27: TOTAL DE AJUSTES
B28: (-) Costs
B29: Redemption Cost
B30: TOTAL DE AJUSTES
B31: Coop Media
B32: TOTAL DE AJUSTES
B33: BV & EAN
B34: TOTAL DE AJUSTES
... B46: Personnel
A47: 3311170 | B47: Vale Refeição | C47: SG&A | D47: Personnel
A48: 3311110 | B48: Gratificações | C48: SG&A | D48: Personnel
A49: 3311130 | B49: Assistência Médica | C49: SG&A | D49: PersonnelNF
A50: 3313200 | B50: Estacionamento | C50: SG&A | D50: PersonnelNF
A51: 3311001 | B51: Cost Sharing | C51: SG&A | D51: Personnel
A52: 3311270 | B52: Multas e Indenizações | C52: SG&A | D52: Personnel
A53: 3311220 | B53: Outros Benefícios | C53: SG&A | D53: PersonnelNF
A54: 3311070 | B54: Férias | C54: SG&A | D54: Personnel
A55: 3311080 | B55: Triênio | C55: SG&A | D55: Personnel
...

Sheet noverdepacote
A1: Conta | B1: Descrção | C1: Grupo | D1: SubGrupo
B2: Net Revenues
B3: Gross Revenues
B4: Spread
B5: TOTAL DE AJUSTES
B6: Redemption
B7: TOTAL DE AJUSTES
B8: Breakage
B9: TOTAL DE AJUSTES
B10: Service Revenues
B11: Fee
B12: TOTAL DE AJUSTES
B13: Service Revenues - Dotz Pay
... B15: Service Revenues - Noverde
A16: 71510000003 | B16: Outras Receitas Financeiras | C16: Gross Revenues | D16: Service Revenues - Noverde
A17: 71999009004 | B17: Fee de Performance | C17: Gross Revenues | D17: Service Revenues - Noverde
A18: 71999009007 | B18: Receita EP | C18: Gross Revenues | D18: Service Revenues - Noverde
A19: 71999009002 | B19: Provisao Servicos Prestados - Mercado Interno | C19: Gross Revenues | D19: Service Revenues - Noverde
A20: 71999009012 | B20: Receita Seguro Prestamista | C20: Gross Revenues | D20: Service Revenues - Noverde
A21: 71999009010 | B21: Receita de Cobrança | C21: Gross Revenues | D21: Service Revenues - Noverde
A22: 71999009008 | B22: Receita FGTS | C22: Gross Revenues | D22: Service Revenues - Noverde
A23: 71999009011 | B23: Outras Receitas NoVerde | C23: Gross Revenues | D23: Service Revenues - Noverde
A24: 71999009009 | B24: Receita BNPL | C24: Gross Revenues | D24: Service Revenues - Noverde
A25: 71999009014 | B25: Provisão Receita Seguro Prestamista | C25: Gross Revenues | D25: Service Revenues - Noverde
A26: 71999009016 | B26: Receita de Risk As A Service | C26: Gross Revenues | D26: Service Revenues - Noverde
A27: 71999009017 | B27: Receita de Referral | C27: Gross Revenues | D27: Service Revenues - Noverde
B28: TOTAL DE AJUSTES
B29: (-) Sales Tax & Deductions
B30: Pis
A31: 81933000003 | B31: Pis - Serviços Prestados | C31: (-) Sales Tax & Deductions | D31: Sales Tax
B32: TOTAL DE AJUSTES
B33: Cofins
A34: 81930003003 | B34: Cofins - Serviços Prestados | C34: (-) Sales Tax & Deductions | D34: Sales Tax
B35: TOTAL DE AJUSTES
B36: ISS
A37: 81925001001 | B37: (-) ISS sobre Vendas | C37: (-) Sales Tax & Deductions | D37: Sales Tax
B38: TOTAL DE AJUSTES
B39: Deductions
A40: 81706000002 | B40: (-)Cofins Crédito sobre insumos | C40: (-) Sales Tax & Deductions | D40: Deductions
A41: 81703003002 | B41: (-)Pis Crédito sobre insumos | C41: (-) Sales Tax & Deductions | D41: Deductions
...

Sheet paypacote
A1: Conta | B1: Descrção | C1: Grupo | D1: SubGrupo
B2: Net Revenues
B3: Gross Revenues
B4: Spread
B5: TOTAL DE AJUSTES
B6: Redemption
B7: TOTAL DE AJUSTES
B8: Breakage
B9: TOTAL DE AJUSTES
B10: Service Revenues
B11: Fee
B12: TOTAL DE AJUSTES
B13: Service Revenues - Dotz Pay
A14: 71795210001 | B14: Tarifa 2a via de cartão | C14: Gross Revenues | D14: Service Revenues - Dotz Pay
A15: 71999009007 | B15: Tarifa de Inatividade | C15: Gross Revenues | D15: Service Revenues - Dotz Pay
A16: 71799003002 | B16: Tarifa Recarga Celular | C16: Gross Revenues | D16: Service Revenues - Dotz Pay
A17: 71999009005 | B17: Receita de Exclusividade | C17: Gross Revenues | D17: Service Revenues - Dotz Pay
A18: 71799003004 | B18: Comissão EC - MDR | C18: Gross Revenues | D18: Service Revenues - Dotz Pay
A19: 71795227001 | B19: Tarifa de Saque | C19: Gross Revenues | D19: Service Revenues - Dotz Pay
A20: 71999009006 | B20: Receita de Intermediação | C20: Gross Revenues | D20: Service Revenues - Dotz Pay
A21: 71799003005 | B21: Comissão Cartão de Crédito | C21: Gross Revenues | D21: Service Revenues - Dotz Pay
A22: 71705004001 | B22: Tarifa Recarga | C22: Gross Revenues | D22: Service Revenues - Dotz Pay
B23: TOTAL DE AJUSTES
B24: Service Revenues - Noverde
B25: TOTAL DE AJUSTES
B26: (-) Sales Tax & Deductions
B27: Pis
A28: 81933000003 | B28: Pis - Serviços Prestados | C28: (-) Sales Tax & Deductions | D28: Sales Tax
A29: 81933000002 | B29: Pis - Outras Receitas Operacionais | C29: (-) Sales Tax & Deductions | D29: Sales Tax
B30: TOTAL DE AJUSTES
B31: Cofins
A32: 81930003003 | B32: Cofins - Serviços Prestados | C32: (-) Sales Tax & Deductions | D32: Sales Tax
A33: 81930003002 | B33: Cofins- Outras Receitas Operacionai | C33: (-) Sales Tax & Deductions | D33: Sales Tax
B34: TOTAL DE AJUSTES
B35: ISS
A36: 81925001001 | B36: (-) ISS sobre Vendas | C36: (-) Sales Tax & Deductions | D36: Sales Tax
B37: TOTAL DE AJUSTES
B38: Deductions
A39: 81706000002 | B39: (-)Cofins Crédito sobre insumos | C39: (-) Sales Tax & Deductions | D39: Deductions
A40: 81703003002 | B40: (-)Pis Crédito sobre insumos | C40: (-) Sales Tax & Deductions | D40: Deductions
...

Sheet cbsmfornecedor
A1: Código do PN | B1: Nome do PN | C1: CNPJ | D1: Saldo do parceiro de negócios | E1: Parceiro | F1: Início | G1: Cidade | H1: Estado | I1: Número ID | J1: Inativo | K1: POS Estabelecimento | L1: Cod. DOTZ | M1: Característica 16 | N1: Saldo | O1: Nome fantasia | P1: E-mail | Q1: Cod Estab | R1: Rua do destinatário | S1: Moeda do PN | T1: Data de atualização | U1: [Act]-Item Fluxo de Caixa | V1: Moeda padrão | W1: Endereço de cobrança: país/região | X1: Visualizar PN no Portal?
A2: C000001 | B2: A Universal | D2: 0 | F2: 40816 | J2: Y | L2: 43719 | M2: N | N2: 0 | S2: ## | T2: 40949 | V2: Real | W2: Brasil
A3: C000003 | B3: Acabamentos Bel Lar Ltda | C3: 17.311.465/0001-66 | D3: 0 | E3: Bel Lar | F3: 40816 | G3: Belo Horizonte | H3: MG | J3: N | L3: 1564348 | M3: N | N3: 0 | R3: Pedro II | S3: ## | T3: 43355 | V3: Real | W3: Brasil
A4: C000004 | B4: ALTA ENERGIA FRANCHISING LTDA | C4: 08.274.966/0001-29 | D4: 0 | E4: Academia Alta Energia | F4: 40816 | G4: Belo Horizonte | H4: MG | J4: N | L4: 1573280 | M4: N | N4: 0 | P4: comercial@altaenergia.com.br | R4: Dos Inconfidentes | S4: ## | T4: 42578 | V4: Real | W4: Brasil
A5: C000006 | B5: Acf - Correios | D5: 0 | F5: 40816 | J5: Y | L5: 1732963 | M5: N | N5: 0 | S5: ## | T5: 41319 | V5: Real | W5: Brasil
A6: C000008 | B6: Alecred Promotora Negocios Cres Ltda | C6: 09.547.644/0001-79 | D6: 0 | E6: Ale | F6: 40816 | G6: Natal | H6: RN | J6: N | L6: 1077750 | M6: N | N6: 0 | P6: cptrocas@dotz.com | R6: Manoel de Castro | S6: ## | T6: 44019 | V6: Real | W6: Brasil
A7: C000009 | B7: ALESAT COMBUSTIVEIS S.A. | C7: 23.314.594/0001-00 | D7: 0 | E7: Ale | F7: 40816 | G7: NATAL | H7: RN | J7: N | L7: 290058 | M7: N | N7: 0 | P7: jonatas.braz@ale.com.br | R7: MANOEL DE CASTRO 1170 | S7: ## | T7: 43804 | V7: Real | W7: Brasil
A8: C000010 | B8: Decminas Distribuicao e Logistica S.A. | C8: 07.399.636/0001-05 | D8: 0 | E8: APOIO | F8: 40816 | G8: Contagem | H8: MG | J8: N | L8: 1160653 | M8: N | N8: 0 | O8: cptrocas@dotz.com | P8: cptrocas@dotz.com | R8: Trajano Araujo Viana | S8: ## | T8: 42384 | V8: Real | W8: Brasil
A9: C000011 | B9: Ambiental | D9: 0 | F9: 40816 | J9: Y | L9: 43724 | M9: N | N9: 0 | S9: ## | T9: 41327 | V9: Real | W9: Brasil
A10: C000012 | B10: América Comercial Ltda | C10: 54.805.247/0001-04 | D10: 0 | E10: América | F10: 40816 | G10: São Paulo | H10: SP | J10: N | L10: 1468376 | M10: N | N10: 0 | P10: amnvj@restauranteamerica.com.br; vitornascimento@restauranteamerica.com.br | R10: Nove De Julho | S10: ## | T10: 41647 | V10: Real | W10: Brasil
A11: C000013 | B11: Amteas Praia Hotel Ltda | C11: 06.067.156/0001-76 | D11: 0 | E11: Atlantica Hotels | F11: 40816 | G11: Niteroí | H11: RJ | J11: N | L11: 289447 | M11: N | N11: 0 | P11: contasapagar.qnrj@atlanticahotels.com.br | R11: Professor Alvaro Caetano | S11: ## | T11: 42145 | V11: Real | W11: Brasil
A12: C000014 | B12: Anália Franco Serviços De Alimentação Ltda | C12: 03.578.412/0001-00 | D12: 0 | E12: América | F12: 40816 | G12: São Paulo | H12: SP | J12: N | L12: 1468376 | M12: N | N12: 0 | P12: amanf@restauranteamerica.com.br; vitornascimento@restauranteamerica.com.br | R12: Regente Feijo | S12: ## | T12: 41647 | V12: Real | W12: Brasil
A13: C000015 | B13: DECMINAS DISTRIBUICAO E LOGISTICA S.A. | C13: 07.399.636/0002-88 | D13: 0 | E13: APOIO | F13: 40816 | G13: contagem | H13: MG | J13: N | L13: 1451871 | M13: N | N13: 0 | O13: cptrocas@dotz.com | P13: cptrocas@dotz.com | R13: BR-040, KM 688 PV03 | S13: ## | T13: 42619 | V13: Real | W13: Brasil
A14: C000017 | B14: Area Parking | D14: 0 | F14: 40816 | J14: Y | L14: 1013288 | M14: N | N14: 0 | S14: ## | T14: 41319 | V14: Real | W14: Brasil
A15: C000019 | B15: Assist- Card Do Brasil Ltda | C15: 00.027.571/0001-10 | D15: 0 | E15: Assist-Card | F15: 40816 | G15: São Paulo | H15: SP | J15: N | L15: 1584984 | M15: N | N15: 0 | R15: Paulista | S15: ## | T15: 41187 | V15: Real | W15: Brasil
A16: C000021 | B16: Associação Dos Lojistas Leitura Ltda | C16: 07.470.391/0001-57 | D16: 0 | E16: Leitura | F16: 40816 | G16: BELO HORIZONTE | H16: MG | J16: N | L16: 1714099 | M16: N | N16: 0 | P16: renataall@leitura.com.br; oberdan@leitura.com.br | R16: GETULIO VARGAS 668 668 SLJ | S16: ## | T16: 43182 | V16: Real | W16: Brasil
A17: C000023 | B17: Associação Monte Azul | D17: 0 | F17: 40816 | J17: Y | L17: 43728 | M17: N | N17: 0 | S17: ## | T17: 41319 | V17: Real | W17: Brasil
A18: C000024 | B18: Atlantica Hotels Internacional Brasil Ltda | C18: 02.223.966/0001-13 | D18: 80702.81 | E18: Atlantica Hotels | F18: 40816 | G18: BARUERI | H18: SP | J18: N | L18: 290689 | M18: N | N18: 0 | P18: mkthoteis.ahi@atlanticahotels.com.br; gsminatel@atlanticahotels.com.br | R18: RIO NEGRO 585 AND 13 | S18: ## | T18: 45628 | V18: Real | W18: Brasil
A19: C000025 | B19: Atlantica Hotels Internacional Brasil Ltda | C19: 02.223.966/0057-78 | D19: 0 | E19: Atlantica Hotels | F19: 40816 | G19: Brasília | H19: DF | J19: N | L19: 1013296 | M19: N | N19: 0 | R19: SHN | S19: ## | T19: 41415 | V19: Real | W19: Brasil
A20: C000026 | B20: Atlantica Hotels Internacional Brasil Ltda | C20: 02.223.966/0051-82 | D20: 0 | E20: Atlantica Hotels | F20: 40816 | G20: Rio de Janeiro | H20: RJ | J20: N | L20: 1013296 | M20: N | N20: 0 | R20: Barata Ribeiro | S20: ## | T20: 41415 | V20: Real | W20: Brasil
A21: C000027 | B21: ATOMO PROPAGANDA CONVENCOES E EVENTOS LTDA | C21: 05.081.854/0001-63 | D21: 0 | E21: Atomo | F21: 40816 | G21: Santana de Parnaíba | H21: SP | J21: N | L21: 1592264 | M21: N | N21: 0 | R21: Tchucaramanis | S21: ## | T21: 41375 | V21: Real | W21: Brasil
A22: C000028 | B22: Automax Comercial Ltda | C22: 20.994.976/0001-34 | D22: 0 | E22: Automax | F22: 40816 | G22: Belo Horizonte | H22: MG | J22: N | L22: 1157149 | M22: N | N22: 0 | P22: eliana@automaxfiat.com.br; edvania@automaxfiat.com.br | R22: Raja Gabaglia | S22: ## | T22: 43082 | V22: Real | W22: Brasil
A23: C000029 | B23: Azul Music | C23: 71.874.077/0001-39 | D23: 0 | F23: 40816 | G23: SAO PAULO | H23: SP | J23: Y | L23: 1401633 | M23: N | N23: 0 | R23: FERNANDES MOREIRA | S23: ## | T23: 41327 | V23: Real | W23: Brasil
A24: C000030 | B24: Azul Music | D24: 0 | F24: 40816 | J24: Y | L24: 1401633 | M24: N | N24: 0 | S24: ## | T24: 41319 | V24: Real | W24: Brasil
A25: C000031 | B25: AMERICANAS S.A - EM RECUPERACAO JUDICIAL | C25: 00.776.574/0006-60 | D25: 495180.12 | E25: AMERICANAS | F25: 40816 | G25: Rio de Janeiro | H25: RJ | J25: N | L25: 1013253 | M25: N | N25: 0 | R25: Sacadura Cabral | S25: ## | T25: 45964 | V25: Real | W25: Brasil
A26: C000032 | B26: AMERICANAS S.A. | C26: 00.776.574/0006-60 | D26: 0 | E26: Submarino | F26: 40816 | G26: Rio de Janeiro | H26: RJ | J26: N | L26: 1006739 | M26: N | N26: 0 | R26: Sacadura Cabral | S26: ## | T26: 44410 | V26: Real | W26: Brasil
